<xml version="1.0"?>
<robot xmlns:xacro="http://www.ros.org/wiki/xacro" >

    <xacro include filename="intertial_macros.xacro"/>

    <material name"white">
        <color rgba="1 1 1 1"/>
    </material>

    <material name"orange">
        <color rgba="1 0.3 0.1 1"/>
    </material>

    <material name"blue">
        <color rgba="0.2 0.2 1 1"/>
    </material>

    <material name"black">
        <color rgba="0 0 0 1"/>
    </material>


 <!-- Base Link -->

    <link name="base_link">

    </link>

<!-- Chassis Link -->

    <joint name"chassis_joint" type="fixed">
        <parent link="base_link"/>
        <child link="chassis"/>
        <origin xyz="-0.1 0 0"/>
    </joint>

    <link name="chassis">
        <visual>
            <origin xyz="0.15 0 0.075" rpy="0 0 0"/>
            <geometry>
                <box size="0.3 0.3 0.15"/> #measurement for the chassis
            </geometry>
            <material name="white"/>
        </visual>
        <collision>
            <origin xyz="0.15 0 0.075" rpy="0 0 0"/>
            <geometry>
                <box size="0.3 0.3 0.15"/> #measurement for the chassis
            </geometry>
        </collision>
        <xacro:insert_box mass="0.5" x=0.3 y=0.3 z=0.15/>
            <origin xyz="0.15 0 0.075" rpy="0 0 0"/>
        </xacro:intertial_box>
    </link>

    <!-- Left Wheel Link -->

    <joint name="left_wheel_joint" type="continuous">
        <parent link="base_link"/>
        <child link="left_wheel"/>
        <origin xyz="0 0.175 0" rpy="-${pi/2} 0 0"/>
        <axis xyz="0 0 1"/> 	
    </joint>

    <link name="left_wheel">
        <visual>
            <geometry>
                <cylinder radius="0.0342" length="0.03"/>
            </geometry>
            <material name="blue"/>
        </visual>
        <collision>
            <geometry>
                <cylinder radius="0.0342" length="0.03"/>
            </geometry>
        </collision>
            <xacro:insert_cylinder mass="0.1" length="0.03" radius="0.0342"/>
            <origin xyz="0 0 0" rpy="0 0 0"/>
        </xacro:insert_cylinder>
    </link>

        <!-- Right Wheel Link -->

    <joint name="right_wheel_joint" type="continuous">
        <parent link="base_link"/>
        <child link="left_wheel"/>
        <origin xyz="0 -0.175 0" rpy="${pi/2} 0 0"/>
        <axis xyz="0 0 -1"/> 	
    </joint>

    <link name="right_wheel">
        <visual>
            <geometry>
                <cylinder radius="0.0342" length="0.03"/>
            </geometry>
            <material name="blue"/>
        </visual>
        <collision>
            <geometry>
                <cylinder radius="0.0342" length="0.03"/>
            </geometry>
        </collision>
        </collision>
            <xacro:insert_cylinder mass="0.1" length="0.03" radius="0.0342"/>
            <origin xyz="0 0 0" rpy="0 0 0"/>
        </xacro:insert_cylinder>
    </link>

    <!-- Caster Wheel Link -->

    <joint name = "caster_wheel_joint" type="fixed">
        <parent link="chassis"/>
        <child link="caster_wheel"/>
        <origin xyz="0.24 0 0" rpy="0 0 0"/>
    </joint>

    <link name="caster_wheel">
        <visual>
            <geometry>
                <sphere radius="0.0342"/>
            </geometry>
            <material name="black"/>
        </visual>
        <collision>
            <geometry>
                <sphere radius="0.0342"/>
            </geometry>
        </collision>
        </collision>
            <xacro:insert_sphere mass="0.1" radius="0.0342"/>
            <origin xyz="0 0 0" rpy="0 0 0"/>
        </xacro:insert_sphere>
    </link> 	

</robot>